Workbook

Sheet 1_Geometria
B1: FIORA IC — Planilha de Setup CFD/STAR-CCM+ | v4.0 (18/Mai/2026)
B2: ABA 1 — GEOMETRIA DO REATOR
B4: PARÂMETROS DE ENTRADA (Inputs — azul = editável)
B5: Volume útil do reator (V) | C5: 50 | D5: m³ | E5: Proposta contratual
B6: Relação H/D | C6: 7 | D6: — | E6: Stage 1 / Stage 2
B7: Diâmetro interno de referência (D_ref) | C7: 2.09 | D7: m | E7: Stage 1 — verificar via cálculo
B8: Altura útil de referência (H_ref) | C8: 14.6 | D8: m | E8: Stage 1 — verificar via cálculo
B10: CÁLCULOS DE GEOMETRIA (verde = calculado)
B11: Diâmetro interno calculado D = (4V / π·HD)^(1/3) | C11: =(4*C5/(PI()*C6))^(1/3) | D11: m | E11: De V e H/D
B12: Altura útil calculada H = D × (H/D) | C12: =C11*C6 | D12: m
B13: Área da seção transversal A = π·D²/4 | C13: =PI()*C11^2/4 | D13: m²
B14: Volume calculado verificação V_calc = A × H | C14: =C13*C12 | D14: m³ | E14: Deve ≈ C5
B15: Desvio D_calc vs D_ref | C15: =(C11-C7)/C7*100 | D15: % | E15: Aceitável < 5%
B16: Desvio H_calc vs H_ref | C16: =(C12-C8)/C8*100 | D16: % | E16: Aceitável < 5%
B18: POSIÇÃO DOS SEPARADORES INTERNOS
B19: Nível inferior (20% da H útil) | C19: =C12*0.2 | D19: m | E19: A partir da base
B20: Nível intermediário (40% da H útil) | C20: =C12*0.4 | D20: m
B21: Nível superior (60% da H útil) | C21: =C12*0.6 | D21: m
B22: Ângulo sep. inferior (faixa ref.) | C22: 47.5 | D22: ° | E22: Faixa 45–50°
B23: Ângulo sep. intermediário (faixa ref.) | C23: 52.5 | D23: ° | E23: Faixa 50–55°
B24: Ângulo sep. superior (faixa ref.) | C24: 57.5 | D24: ° | E24: Faixa 55–60°
B26: ENTRADAS TANGENCIAIS INFERIORES
B27: Número de entradas | C27: 6 | D27: — | E27: Espaçamento angular 60°
B28: Inclinação ascendente | C28: 7 | D28: ° | E28: ★ v2.0: valor exato confirmado Vinícius 16/05
A29: Ângulo tangencial (com a radial) — bocais | B29: 80 | C29: ° | D29: Vinícius 16/05 18:04 — valor exato (caso base C0)
A31: TOPO TOROESFÉRICO CONVEXO E SAÍDAS — ★ ATUALIZADO v2.0
A32: Tipo de topo | B32: Toroesférico CONVEXO (domo) | D32: ★ v2.0: CONVEXO, não côncavo — Vinícius 16/05 18:04
A33: Altura do domo acima do cilindro (D/8) | B33: =C7/8 | C33: m | D33: ★ FIX v3.0: D/8 (era 12,775 — fórmula errada)
A34: Topo do trecho cilíndrico | B34: =C8-C7/8 | C34: m | D34: ★ FIX v3.0: H − TOP_DEPTH (era 14,6 — era altura total)
A35: Ápice do domo (ponto mais alto) | B35: =C8 | C35: m | D35: ★ FIX v3.0: =C8 (era =B8, retornava texto)
A36: Saída biogás central (ápice) | B36: DN100 central | D36: Pressure Outlet no STAR-CCM+
A37: Saída efluente lateral | B37: DN100, z=14,20m, az=180° | D37: Pressure Outlet — controla nível

Sheet 2_Vazoes_Velocidades
B1: ABA 2 — VAZÕES E VELOCIDADES (Condições de Contorno)
B3: INPUTS DE PROCESSO
B4: Vazão afluente (Q_af) | C4: 50 | D4: m³/d | E4: Máximo do piloto
B5: Fator de recirculação líquida (f_recirc) | C5: 7 | D5: — | E5: 7× Q_af
B6: Densidade do líquido (ρ_L) | C6: 995 | D6: kg/m³ | E6: Vinhaça ≈ água a 35°C
B7: Viscosidade dinâmica do líquido (μ_L) | C7: 0.00072 | D7: Pa·s | E7: Água 35°C ≈ 7.2×10⁻⁴
B8: N° de entradas tangenciais | C8: 6 | D8: — | E8: Ref. Aba 1
B9: Área transversal do reator (A_reator) — via Aba 1 | C9: ='1_Geometria'!C13 | D9: m²
B11: VAZÕES CALCULADAS
B12: Recirculação líquida Q_rec = f × Q_af | C12: =C5*C4 | D12: m³/d
B13: Vazão total inferior Q_tot = Q_af + Q_rec | C13: =C4+C12 | D13: m³/d
B14: Vazão total inferior em m³/h | C14: =C13/24 | D14: m³/h
B15: Vazão total inferior em m³/s | C15: =C13/86400 | D15: m³/s
B16: Vazão efluente (saída topo) Q_ef = Q_af | C16: =C4/86400 | D16: m³/s | E16: Igual a Q_af (regime contínuo)
B18: VELOCIDADES CALCULADAS
B19: Vel. ascensional média global (V_up = Q_tot / A) | C19: =C15/C9 | D19: m/s | E19: Velocidade superficial ascensional
B20: V_up em m/h | C20: =C19*3600 | D20: m/h | E20: Lit.: ≥ 2–8 m/h para IC
A21: Diâmetro nominal do bocal (DN80 — Vinícius) | B21: 0.08 | C21: m | D21: ★ NOVO v3.0: DN80 confirmado — Vinícius 16/05 18:04
B22: ENTRADAS TANGENCIAIS — DIMENSIONAMENTO
B23: Área total de entrada sugerida (10% da área transversal) | C23: =C9*0.1 | D23: m² | E23: Ponto de partida; ajustar no CAD
B24: Área por bocal (A_bocal = A_tot / N) | C24: =C23/C8 | D24: m²
B25: Diâmetro equivalente por bocal (d_bocal) | C25: =B21 | D25: m | E25: ★ FIX v3.0: usa DN80 confirmado (não 269 mm calculado de 10% da área)
B26: d_bocal em mm | C26: =C25*1000 | D26: mm | E26: Verificar com croqui do Vinícius
B27: Vel. de entrada por bocal (V_bocal = Q_tot/s / A_tot) | C27: =C15/C8/(PI()*(B21/2)^2) | D27: m/s | E27: ★ FIX v3.0: Q_por_bocal/A_DN80 (era Q_total/A_total → 11× menor)
B28: Número de Reynolds do bocal | C28: =C6*C27*C25/C7 | D28: — | E28: ★ Auto-atualizado: agora ~17.020 (era 5.038)
B30: NÚMERO DE REYNOLDS GLOBAL (corpo do reator)
B31: Re_global = ρ·V_up·D / μ | C31: =C6*C19*('1_Geometria'!C11)/C7 | D31: — | E31: Re > 4000 → turbulento; justifica modelo k-ε
B32: Regime de escoamento | C32: =IF(C31>4000,"TURBULENTO (k-ε válido)",IF(C31>2300,"TRANSITÓRIO","LAMINAR"))
A34: DIFUSORES DE MICROBOLHAS — ★ NOVO v2.0 (12× DN250 no FUNDO)
A35: Quantidade de difusores | B35: 12 | C35: — | D35: ★ 12 × DN250 — Vinícius 16/05 16:50 (NÃO 4×DN60 parede)
A36: Diâmetro de cada difusor | B36: 0.250 | C36: m | D36: DN250 — confirmado Vinícius 16/05 16:50
A37: Localização | B37: Fundo do reator (não parede lateral) | D37: ★ v2.0: FUNDO entre os bocais
A38: Disposição | B38: 6 setores × 2 difusores (az: 30,90,150,210,270,330°) | D38: r_int=0,35m / r_ext=0,80m
A39: Fração recirculada de biogás | B39: 0.40 | C39: — | D39: 40% — confirmado Vinícius
A40: Composição gás recirculado | B40: CH₄ 65% / CO₂ 34% / H₂S 1% / H₂ traço | D40: ★ v2.0 — Vinícius 16/05 18:04
A41: Diâmetro das bolhas geradas (CFD) | B41: 0.002 | C41: m | D41: d₃₂ = 2 mm — adotado
A42: Vazão unitária por difusor | B42: 2–4 Nm³/h | C42: Nm³/h | D42: Vinícius 16/05 16:50
A43: BC no STAR-CCM+ | B43: Mass Flow Inlet | D43: 12 faces circulares no fundo via Imprint
A45: SAÍDAS (OUTLETS) — ★ ATUALIZADO v2.0 — 6 tipos de BC
A46: Saída biogás — central topo | B46: Pressure Outlet | C46: DN100 central, ápice domo z=14,6m | D46: P_rel=0
...

Sheet 3_Fases_Propriedades
B1: ABA 3 — PROPRIEDADES DAS FASES (Setup E-E Trifásico)
B3: FASE LÍQUIDA (Fase Contínua Primária)
B4: Fluido de referência | C4: Vinhaça / Água (≈ água 35°C)
B5: Temperatura | C5: 35 | D5: °C
B6: Densidade (ρ_L) | C6: 995 | D6: kg/m³ | E6: Água 35°C; vinhaça pode ser 1000–1020
B7: Viscosidade dinâmica (μ_L) | C7: 0.00072 | D7: Pa·s | E7: Água 35°C
B8: Fração volumétrica inicial (α_L) | C8: 0.92 | D8: — | E8: 1 - alfa_G - alfa_S (estimativa inicial)
B10: FASE GASOSA (Fase Dispersa — Biogás)
B11: Composição adotada (caso base simplificado) | C11: CH₄ 65% / CO₂ 34% / H₂S 1% / H₂ traço
B12: Densidade do gás (ρ_G) a 35°C e 1.5 kgf/cm² | C12: 2.5 | D12: kg/m³ | E12: Estimativa; P≈147 kPa abs, ρ≈2.3–2.8 kg/m³
B13: Viscosidade dinâmica gás (μ_G) | C13: 1.2e-05 | D13: Pa·s | E13: CH₄/CO₂ aprox.
B14: Diâmetro de bolha (d_b) | C14: 0.003 | D14: m | E14: 3 mm — lit.: 1–5 mm em IC/EGSB
B15: Fração volumétrica inicial gás (α_G) | C15: 0.05 | D15: — | E15: Estimativa 5%; ajustar pós-convergência
B16: Taxa de geração de gás (Q_gas) | C16: 0.05 | D16: m³/m³·h | E16: Estimativa exploratória — fonte volumétrica
B18: VELOCIDADE TERMINAL DE BOLHA (verificação)
B19: g (aceleração gravitacional) | C19: 9.81 | D19: m/s²
B20: Vel. terminal bolha — Stokes V_t = (ρ_L−ρ_G)·g·d_b²/(18·μ_L) ⚠ TEÓRICO | C20: =(C6-C12)*C19*C14^2/(18*C7) | D20: m/s | E20: ★ v3.0: STOKES INVÁLIDO para bolhas >0,1mm. Use linhas 21b–21d ↓
B21: V_t em m/h | C21: =C20*3600 | D21: m/h | E21: ★ Comparar com V_real ↓
B22: Re_bolha (Stokes) Re = ρ·V_Stokes·d/μ | C22: =C6*C20*C14/C7 | D22: — | E22: Se Re>>1 → Stokes inválido. Use Schiller-Naumann
B23: FASE SÓLIDA — LODO GRANULAR (Fase Granular E-E)
B24: ⚠ NOTA TÉCNICA: A literatura NÃO registra uso de DEM para reatores de lodo granular
B25: → Abordagem correta: Euleriano-Euleriano (E-E) três fases com modelo granular cinético (KTGF)
B27: Diâmetro médio do grânulo (d_p) | C27: 0.002 | D27: m | E27: 2 mm — faixa 1–3 mm
B28: Densidade do grânulo (ρ_S) | C28: 1460 | D28: ★ v2.0: 1460 kg/m³ (Wang 2009/2010 — EGSB) | E28: ★ v3.0: 1460 = limite superior. Mais comum na lit.: 1.050 (D'Bastiani 2021). Usar como sensibilidade.
B29: Fração volumétrica inicial sólidos (α_S) | C29: 0.03 | D29: — | E29: ★ v3.0: 0,03 = média do reator. NO LEITO (zona inferior) usar α_S=0,35 (Wang 2010)
B30: Verificação: α_L + α_G + α_S deve = 1 | C30: =C8+C15+C29 | D30: — | E30: DEVE SER 1.000
B31: Vel. sedimentação grânulo — Stokes V_sed = (ρ_S−ρ_L)·g·d_p²/(18·μ_L) ⚠ TEÓRICO | C31: =(C28-C6)*C19*C27^2/(18*C7) | D31: m/s | E31: ★ v3.0: STOKES INVÁLIDO para Re>>1 — usar correlação Schiller-Naumann
B32: V_sed em m/h | C32: =C31*3600 | D32: m/h | E32: Lit.: 50–80 m/h; Stokes subestima — referência
B33: Restitution coefficient (e_ss) — granular kinetic | C33: 0.9 | D33: — | E33: Típico para grânulos biológicos
B34: Packing limit (α_S,max) | C34: 0.63 | D34: — | E34: Máximo empacotamento esferas
A36: FASE SÓLIDA 2 — BIOCHAR VEGETAL (E-E Dispersa) — ★ NOVO v2.0
A37: Material | B37: Biochar vegetal / carbonáceo poroso | C37: — | D37: Vinícius — tabela 15/05
A38: Diâmetro médio (d50) | B38: 0.003 | C38: m | D38: 3 mm — Vinícius 15/05 (faixa 2–3mm)
A39: Densidade aparente (ρ_aparente) | B39: 500 | C39: kg/m³ | D39: Vinícius — tabela 15/05
A40: Densidade real / esquelética | B40: 1500 | C40: kg/m³ | D40: Vinícius — tabela 15/05
A41: Porosidade interna | B41: 0.65 | C41: — | D41: 60–70% — adotado 65% (Vinícius)
A42: Esfericidade (φ) | B42: 0.65 | C42: — | D42: Vinícius — tabela 15/05
A43: Fração volumétrica inicial (α_biochar) | B43: 0.01 | C43: — | D43: ~1% — Dosagem 5,0 g/L ÷ ρ_aparente
A44: Concentração equivalente | B44: 5.0 | C44: kg/m³ | D44: 5,0 g/L = 5,0 kg/m³ — Vinícius
A45: Zona de aplicação | B45: Zona inferior (z=0 a z=2,92m) | D45: Abaixo do sep. 20%
...

Sheet 4_Turbulencia_CC
B1: ABA 4 — TURBULÊNCIA (k-ε Realizável) E CONDIÇÕES DE CONTORNO
B3: MODELO DE TURBULÊNCIA RECOMENDADO
B4: Modelo: k-ε Realizável (Realizable k-ε) — fase líquida contínua
B5: Justificativa: melhor concordância com PIV em reatores cilíndricos (Cisneros et al. 2021; Sindall et al.)
B6: Wu (2011): k-ω Std e k-ε Realizável são os mais adequados para mistura em reatores AD
B7: Tabela de revisão (D'Bastiani 2023 WR): k-ε Standard/Realizável dominante em UASB/EGSB/IC
B9: INTENSIDADE TURBULENTA E ESCALA — INLET BC
B10: Intensidade turbulenta (I) — tubulações em regime turbulento | C10: =0.16*(('2_Vazoes_Velocidades'!C28)^(-1/8)) | D10: — | E10: I = 0.16·Re^(−1/8) — correlação padrão
B11: I em % | C11: =C10*100 | D11: %
B12: Comprimento de mistura (l = 0.07·d_bocal) | C12: =0.07*('3_Fases_Propriedades'!C27*0+('2_Vazoes_Velocidades'!C25)) | D12: m | E12: Hidráulico dh = d_bocal
B13: Energia cinética turbulenta k_inlet | C13: =1.5*('2_Vazoes_Velocidades'!C27*C10)^2 | D13: m²/s² | E13: ★ Auto-atualizado v3.0: agora ~1,08×10⁻⁴ m²/s² (era 8,3×10⁻⁷)
B14: Taxa dissipação turbulenta ε_inlet = Cμ^(3/4)·k^(3/2)/l | C14: =0.09^0.75*C13^1.5/C12 | D14: m²/s³ | E14: ★ Auto-atualizado v3.0: agora ~9,7×10⁻⁶ m²/s³ (era 6,6×10⁻⁹)
B16: CONDIÇÕES DE CONTORNO — RESUMO STAR-CCM+
B17: Inlet (6 bocais tangenciais) | C17: Velocity Inlet | D17: V_bocal (Aba 2, C27) | E17: k e ε de Aba 4 C13/C14
B18: Outlet (saída topo) | C18: Pressure Outlet | D18: P_gage = 0 Pa (ref.) | E18: Backflow: valores de inlet
B19: Parede do reator | C19: No-Slip Wall | D19: — | E19: Wall function (y+ ≈ 30–300 target)
B20: Separadores internos | C20: No-Slip Wall | D20: — | E20: Wall function
B21: Tubo de retorno central | C21: Interface / Wall | D21: — | E21: Verificar geometria
B23: CRITÉRIOS DE CONVERGÊNCIA E MALHA
B24: Resíduos de continuidade/momento | C24: < 1×10⁻⁴ (ou 10⁻³ para screening)
B25: Monitoramento de V_up média | C25: Variação < 1% em 100 iterações
B26: Monitoramento de α_G média | C26: Variação < 2%
B27: Time step (transiente) | C27: Δt = 0.01–0.05 s (Pan et al. 2017: Δt=0.02 s)
B28: Tempo simulado mínimo | C28: ≥ 5 × TRH hidráulico do reator
B29: TRH do reator | C29: ='1_Geometria'!C5/('2_Vazoes_Velocidades'!C4/24)
B30: Target y+ (paredes) | C30: 30–300 (k-ε Wall Function padrão)
B31: Malha — base sugerida | C31: 500k–2M células 3D (lit.: IC full scale ≈ 2.3M, D'Bastiani 2021)
B32: TRH calculado (V/Q_af) em horas | C32: ='1_Geometria'!C5/('2_Vazoes_Velocidades'!C4/24) | D32: h
B33: Tempo mínimo de simulação transiente (5×TRH) | C33: =C32*5*3600 | D33: s | E33: Em segundos para setup STAR-CCM+
A35: MAPA COMPLETO DE BOUNDARY CONDITIONS — ★ ATUALIZADO v2.0
A36: # | B36: Superfície / Região | C36: Tipo BC | D36: Fase | E36: Valor / Observação
A37: 1 | B37: 6 faces externas bocais (DN80) | C37: Velocity Inlet | D37: Líquido | E37: Q=66,7 m³/d/bocal | T=35°C | incl.7° | tang.80° anti-horário
A38: 2 | B38: Face topo do DN100 (retorno) | C38: Velocity Inlet | D38: Líquido | E38: Q=350 m³/d | dir.−Z | T=35°C
A39: 3 | B39: 12 difusores DN250 no fundo | C39: Mass Flow Inlet | D39: Gás (biogás) | E39: ṁ=(40%×Q_biogás)/12 | CH₄65%/CO₂34%/H₂S1% | d_bolha=2mm
A40: 4 | B40: 4 furos DN50 (paredes laterais) | C40: Pressure Outlet | D40: Multifásico | E40: P_rel=0 | z=2,92/5,84/8,76/13,87m | az=0°
A41: 5 | B41: Furo DN100 central (ápice domo) | C41: Pressure Outlet | D41: Gás | E41: P_rel=0 — saída primária biogás
A42: 6 | B42: Furo DN100 lateral (z=14,20m) | C42: Pressure Outlet | D42: Líquido | E42: P_rel=0 — controla nível operacional | az=180°
A43: 7 | B43: Parede cilíndrica + domo + fundo | C43: No-slip Wall | D43: — | E43: Rugosidade=0 | y⁺=30–100 (k-ε Realizable)
A44: 8 | B44: 8 placas separadoras | C44: Baffle No-slip | D44: — | E44: Ambos os lados | borda clipada ao cilindro
A45: 9 | B45: Parede anelar DN100 (baffle) | C45: Baffle No-slip | D45: — | E45: Separa fluxo ↓ (dentro) de ↑ (fora)
...

Sheet 5_Pressao_Operacional
B1: ABA 5 — PRESSÃO OPERACIONAL E BIOGÁS
B3: PRESSÃO E BIOGÁS
B4: Pressão operacional do reator | C4: 1.5 | D4: kgf/cm²
B5: Pressão em Pa absoluta | C5: =C4*98066.5 | D5: Pa abs
B6: Pressão em kPa abs | C6: =C5/1000 | D6: kPa
B7: Pressão manométrica de operação (P_gage) | C7: =C5-101325 | D7: Pa gauge | E7: P_abs - P_atm
B8: Pressão descarga blower | C8: 2 | D8: kgf/cm²
B9: P_blower em Pa abs | C9: =C8*98066.5 | D9: Pa abs
B11: DENSIDADE DO BIOGÁS (CH₄/CO₂) NA PRESSÃO OPERACIONAL
B12: Temperatura operacional (T) | C12: 35 | D12: °C
B13: T em Kelvin | C13: =C12+273.15 | D13: K
B14: Fração molar de CH₄ na corrente (estimativa) | C14: 0.65 | D14: — | E14: ★ v2.0: CH₄65%/CO₂34%/H₂S1% — Vinícius 16/05 18:04
B15: Massa molar mistura (M_mix = yCH4·16 + yCO2·44) | C15: =0.65*16+0.34*44+0.01*34 | D15: g/mol | E15: ★ FIX v3.0: inclui H₂S (era só CH₄+CO₂ → 25,8). Agora 25,7
B16: Densidade biogás — gás ideal ρ = P·M/(R·T) | C16: =C5*(C15/1000)/(8.314*C13) | D16: kg/m³ | E16: R=8.314 J/mol·K; M em kg/mol
B18: NOTA CFD — ABORDAGEM DE PRESSÃO NO STAR-CCM+
B19: No STAR-CCM+, o solver multifásico trabalha com pressão manométrica (gauge).
B20: Definir P_operacional como 'Operating Pressure' = P_abs do reator (Aba 5 C5).
B21: Outlet BC: P_gage = 0 Pa (topo do reator = referência).
B22: A coluna hidrostática é importante: ρ_L × g × H_reator ≈
B23: Pressão hidrostática máxima (base do reator) ΔP_hid = ρ_L·g·H | C23: ='3_Fases_Propriedades'!C6*9.81*'1_Geometria'!C12 | D23: Pa | E23: Informa setup de P operacional
A25: COMPOSIÇÃO DO GÁS RECIRCULADO — ★ NOVO v2.0
A26: Fração CH₄ | B26: 0.65 | C26: — | D26: Vinícius 16/05 18:04
A27: Fração CO₂ | B27: 0.34 | C27: — | D27: Vinícius 16/05 18:04
A28: Fração H₂S | B28: 0.01 | C28: — | D28: ★ v2.0 — Vinícius 16/05 18:04
A29: Fração H₂ | B29: traço | C29: — | D29: Vinícius 16/05 18:04
A30: Massa molar mistura (M_mix) | B30: =0.65*16+0.34*44+0.01*34 | C30: g/mol | D30: Calculado
A31: Densidade gás recirc. (35°C, 1,5 kgf/cm²) | B31: =B30/1000*147100/(8.314*308.15) | C31: kg/m³ | D31: Gás ideal — usar em Mass Flow Inlet

Sheet 6_Nota_DEM_vs_EE
A1: ★ v3.0: nota mantida + adicionadas Abas 8 (Eletrodos), 9 (Cinética+Pós), 10 (Reports), 11 (Matriz). Ver Aba 9 para cálculo H₂/DQO via pós-processamento.
B3: ABA 6 — NOTA TÉCNICA: DEM vs EULERIANO-EULERIANO (Revisão da Literatura)
B4: CONCLUSÃO PRINCIPAL
B5: A literatura especializada em reatores de lodo granular anaeróbio NÃO registra nenhum uso de DEM.
B6: Fonte: D'Bastiani et al. (2023) Water Research 242 — revisão sistemática de todos os papers CFD em AGSRs.
B8: ABORDAGEM DOMINANTE NA LITERATURA
B9: Euleriano-Euleriano (E-E) trifásico: gás + líquido + sólido (granular)
B10: Modelo granular cinético (KTGF - Kinetic Theory of Granular Flow) para a fase sólida
B11: Fase sólida tratada como fluido granular contínuo — NÃO como partículas discretas
B13: POR QUE DEM NÃO É VIÁVEL AQUI?
B14: 1. Escala: reator de 50 m³ com grânulos de 1–3 mm implicaria bilhões de partículas — inviável computacionalmente.
B15: 2. Literatura: nenhum paper encontrado usando DEM ou SPH para AGSRs (D'Bastiani 2023 — busca extensiva).
B16: 3. A proposta menciona 'DEM' mas a própria CAEXPERTS usa STAR-CCM+ com E-E (padrão de mercado).
... B29: Geração de gás pode ser imposta como source term volumétrico constante (estimativa exploratória).

Sheet 7_Difusores_Microbolhas
A1: FIORA IC — ABA 7: DIFUSORES DE MICROBOLHAS — ★ NOVO v2.0
A2: ★ ATUALIZADO v2.0: 12× DN250 no FUNDO (anteriormente 4× DN60 na parede lateral) — Vinícius 16/05/2026 16:50
A4: A. CONFIGURAÇÃO DOS DIFUSORES
A5: Número total de difusores | B5: 12 | C5: — | D5: Vinícius 16/05 16:50
A6: Diâmetro de cada difusor | B6: 0.25 | C6: m | D6: DN250 — Vinícius 16/05 16:50
A7: Número de setores azimutais | B7: 6 | C7: — | D7: Setores entre os bocais
A8: Difusores por setor | B8: 2 | C8: — | D8: 1 interno (r=0,35m) + 1 externo (r=0,80m)
A9: Raio posição interno (r_int) | B9: 0.35 | C9: m | D9: Adotado
A10: Raio posição externo (r_ext) | B10: 0.8 | C10: m | D10: Adotado
A11: Azimutes dos setores | B11: 30,90,150,210,270,330 | C11: ° | D11: Entre os bocais (0,60,120,180,240,300°)
A12: Cota vertical dos difusores | B12: 0.05 | C12: m | D12: No fundo — z≈50mm acima do piso
A14: B. VAZÕES E CONDIÇÕES OPERACIONAIS
A15: Fração de biogás recirculado | B15: 0.4 | C15: — | D15: 40% — confirmado Vinícius
A16: Composição do gás recirculado | B16: CH₄ 65% / CO₂ 34% / H₂S 1% / H₂ traço | D16: ★ v2.0 — Vinícius 16/05 18:04
A17: Diâmetro das bolhas geradas (d₃₂) | B17: 0.002 | C17: m | D17: 2 mm — literatura / Vinícius
A18: Vazão unitária por difusor | B18: 2–4 | C18: Nm³/h | D18: Vinícius 16/05 16:50
A19: Pressão do blower | B19: 2 | C19: kgf/cm² | D19: Vinícius 16/05 16:50
A21: C. POSICIONAMENTO DOS 12 DIFUSORES
A22: Difusor | B22: Setor (az) | C22: Posição | D22: Raio (m) | E22: Notas
A23: D01 | B23: 30° | C23: Interno | D23: 0,35 | E23: Par setor 1
A24: D02 | B24: 30° | C24: Externo | D24: 0,80 | E24: Par setor 1
A25: D03 | B25: 90° | C25: Interno | D25: 0,35 | E25: Par setor 2
A26: D04 | B26: 90° | C26: Externo | D26: 0,80 | E26: Par setor 2
A27: D05 | B27: 150° | C27: Interno | D27: 0,35 | E27: Par setor 3
A28: D06 | B28: 150° | C28: Externo | D28: 0,80 | E28: Par setor 3
A29: D07 | B29: 210° | C29: Interno | D29: 0,35 | E29: Par setor 4
A30: D08 | B30: 210° | C30: Externo | D30: 0,80 | E30: Par setor 4
A31: D09 | B31: 270° | C31: Interno | D31: 0,35 | E31: Par setor 5
A32: D10 | B32: 270° | C32: Externo | D32: 0,80 | E32: Par setor 5
A33: D11 | B33: 330° | C33: Interno | D33: 0,35 | E33: Par setor 6
A34: D12 | B34: 330° | C34: Externo | D34: 0,80 | E34: Par setor 6
A36: D. SETUP NO STAR-CCM+
A37: 1. Imprint | B37: Importar diffusers.step → Imprint Bodies com fluid_domain → cria 12 faces circulares no fundo
A38: 2. Delete | B38: Deletar bodies diffusers.step após Imprint (stubs cumpriram papel)
A39: 3. Nomear | B39: Renomear 12 faces: Inlet_Diffuser_01 a Inlet_Diffuser_12
A40: 4. BC | B40: Tipo: Mass Flow Inlet | Fase: Gás | ṁ = (0,40 × Q_biogás_total) ÷ 12 por difusor
A41: 5. Composição | B41: CH₄: 0,65 | CO₂: 0,34 | H₂S: 0,01 | T=35°C | d_bolha=2mm
A42: 6. Verificar | B42: Geometry Check → 12 faces DN250 geradas corretamente (sem degeneradas)

Sheet 8_Eletrodos
B1: FIORA IC — Planilha de Setup CFD/STAR-CCM+ | v3.0
B2: ABA 8 — ELETRODOS ELETROATIVOS (Ânodo/Cátodo)
A4: PARÂMETROS GEOMÉTRICOS (Vinícius 15/05 16:50 — módulo eletroativo)
A5: Número total de placas | B5: 4 | C5: — | D5: 2 ânodos + 2 cátodos
A6: Altura da placa (ELEC_H) | B6: 2.4 | C6: m | D6: Vinícius — tabela 15/05
A7: Largura da placa (ELEC_W) | B7: 0.52 | C7: m | D7: Vinícius — tabela 15/05
A8: Espessura da placa (ELEC_THICK) | B8: 0.008 | C8: m | D8: 8 mm — padrão eletrodo industrial
A9: Posição radial (ELEC_R_POS = 65% × R_reator) | B9: =0.65*('1_Geometria'!C11/2) | C9: m | D9: 0,65 × R = 0,68 m do centro
A10: Cota base (ELEC_Z_BOT) | B10: 0.25 | C10: m | D10: Vinícius: 'abaixo do 1° separador'
A11: Cota topo (ELEC_Z_TOP = ELEC_Z_BOT + ELEC_H) | B11: =B8+B6 | C11: m | D11: 0,25 + 2,40 = 2,65 m
A12: Cota do Sep. 20% (limite superior permitido) | B12: ='1_Geometria'!C19 | C12: m | D12: Não pode haver overlap
A13: Folga vertical até Sep. 20% | B13: =B11-B10 | C13: m | D13: ✓ Deve ser positivo
A15: ÁREA ELETROATIVA
A16: Área por placa | B16: =B6*B7 | C16: m² | D16: =ELEC_H × ELEC_W ≈ 1,25 m²
A17: Área eletroativa total (4 placas) | B17: =4*B14 | C17: m² | D17: ≈ 5,0 m² — confere com Vinícius
A19: ARRANJO DOS PARES E GAP
A20: Número de pares Ânodo/Cátodo | B20: 2 | C20: — | D20: Par 1 + Par 2
A21: Azimute do Par 1 | B21: 0 | C21: ° | D21: Adotado — simetria diametral
A22: Azimute do Par 2 | B22: 180 | C22: ° | D22: Adotado — diametralmente oposto
A23: Gap FACE-A-FACE (ELEC_GAP_FACE) | B23: 0.03 | C23: m | D23: Vinícius: 'máximo 30 mm' — adotado limite superior
A24: Distância CENTRO-A-CENTRO (c2c = gap + esp.) | B24: =B21+B8 | C24: m | D24: Usado no CAD para posicionar as placas
A26: VERIFICAÇÕES GEOMÉTRICAS (não pode haver conflito)
A27: Raio externo da placa (r_ext = R_POS + W/2) | B27: =B9+B7/2 | C27: m | D27: 0,68 + 0,26 = 0,94 m
A28: Raio interno da placa (r_int = R_POS − W/2) | B28: =B9-B7/2 | C28: m | D28: 0,68 − 0,26 = 0,42 m
A29: Raio do reator | B29: ='1_Geometria'!C11/2 | C29: m | D29: ≈ 1,045 m
A30: Folga radial até parede (R − r_ext) | B30: =B27-B25 | C30: m | D30: ✓ Deve ser > 0,05 m
A31: Raio externo do DN100 (R_RETURN_OUT) | B31: 0.05 | C31: m | D31: DN100/2
A32: Folga radial até DN100 (r_int − R_RETURN_OUT) | B32: =B26-B29 | C32: m | D32: ✓ Deve ser > 0,1 m
A34: BOUNDARY CONDITION NO STAR-CCM+
A35: Tipo de BC | B35: No-slip Wall | C35: — | D35: Sólido inerte — sem eletroquímica no caso base
A36: Nome no STAR-CCM+ | B36: Wall_Electrode_A1 / A2 / C1 / C2 | C36: — | D36: 4 boundaries separadas
A37: Parâmetros elétricos (tensão, corrente, densidade de corrente, transferência iônica) serão implementados na PRÓXIMA ETAPA via módulo Electrochemistry do STAR-CCM+, após validação do caso base hidrodinâmico.
A39: PRÓXIMA ETAPA — ELETROQUÍMICA (FORA DO ESCOPO ATUAL)
A41: ★ v4.0 — VERIFICAÇÃO DE FOLGA CRÍTICA: SEP. 20% × ELETRODOS
A42: Cota topo dos eletrodos (z_top) | B42: =B8+B6 | C42: m | D42: =ELEC_Z_BOT + ELEC_H = 2,65 m
A43: Cota nominal Sep. 20% (= borda inferior das placas) | B43: ='1_Geometria'!C19 | C43: m | D43: 20% × H = 2,92 m
A44: Queda vertical das placas do Sep. 20% | B44: =(0.5*'1_Geometria'!C11/2)*SIN(RADIANS('1_Geometria'!C22)) | C44: m | D44: W/2 × sin(47,5°) = 0,385 m (N=2, W=D/2)
A45: ★ FOLGA = (Sep. 20% base) − (eletrodo topo) | B45: =B43-B42 | C45: m | D45: Deve ser > 50 mm. Calc.: 2,92 − 2,65 = 270 mm ✅

Sheet 9_Regioes_Cinetica_PosProc
B1: FIORA IC — Planilha de Setup CFD/STAR-CCM+ | v3.0
B2: ABA 9 — REGIÕES FUNCIONAIS A/B + CINÉTICA SIMPLIFICADA (Pós-processamento)
A4: DEFINIÇÃO DAS REGIÕES FUNCIONAIS (Stage 2 §8) — Field Functions no STAR-CCM+
A5: Zona A — Região hidrogênica (z do fundo) | B5: 0 → 8,76 m | C5: — | D5: 0% → 60% da altura útil
A6: Zona A — em frame centrado (CFD origem = centro) | B6: −7,30 → +1,46 m | C6: — | D6: z_rel = z − H/2
A7: Zona B — Região metanogênica (z do fundo) | B7: 8,76 → 13,87 m | C7: — | D7: 60% → 95% da altura útil
A8: Zona B — em frame centrado | B8: +1,46 → +6,57 m | C8: — | D8: z_rel = z − H/2
A9: Zona Final — Separação (z do fundo) | B9: 13,87 → 14,60 m | C9: — | D9: 95% → 100% — apenas separação
A11: FIELD FUNCTIONS A CRIAR NO STAR-CCM+ (Tools > Field Functions > New)
A12: Nome: Zone_A | Definition: | B12: ($$Position[2] < 1.46) && ($$Position[2] > -7.30) ? 1.0 : 0.0
A13: Nome: Zone_B | Definition: | B13: ($$Position[2] >= 1.46) && ($$Position[2] < 6.57) ? 1.0 : 0.0
A14: PARÂMETROS CINÉTICOS (Stage 2 §10, §13)
A15: DQO afluente (S_DQO_in) | B15: 25 | C15: kg/m³ | D15: 25.000 mg/L — Stage 2 §2 (faixa 20–30)
A16: Carga orgânica total (L_org) | B16: =B15*'2_Vazoes_Velocidades'!C4 | C16: kg DQO/d | D16: =S_DQO × Q_af ≈ 1.250 kg DQO/d
A17: Constante cinética Região A (k_app,A) | B17: 0.3 | C17: h⁻¹ | D17: Stage 2 §10 — faixa 0,20–0,50
A18: Constante cinética Região B (k_app,B) | B18: 0.08 | C18: h⁻¹ | D18: Stage 2 §13 — faixa 0,05–0,15
A19: Fator estequiométrico H₂ (f_H₂) | B19: 0.05 | C19: kg H₂/kg DQO | D19: EXPLORATÓRIO — variar 0,02 a 0,10
A20: Rendimento de CH₄ (Y_CH₄) | B20: 0.3 | C20: Nm³CH₄/kg DQO | D20: Stage 2 §13 — faixa 0,25–0,32
A22: ESTIMATIVAS PRELIMINARES (validação cruzada com planilha Vinícius)
A23: Volume teórico Região A (V_A = A × h_A) | B23: ='1_Geometria'!C13*'1_Geometria'!C12*0.6 | C23: m³ | D23: 60% × V_reator
A24: Volume teórico Região B (V_B = A × (h_B − h_A)) | B24: ='1_Geometria'!C13*'1_Geometria'!C12*(0.95-0.6) | C24: m³ | D24: 35% × V_reator
A25: Taxa de consumo DQO Região A (r_DQO,A) | B25: =B17/3600*B15*B23 | C25: kg/s | D25: =k_app,A × S_DQO × V_A (assumindo S_DQO constante)
A26: Taxa de consumo DQO Região B (r_DQO,B) | B26: =B18/3600*B15*0.3*B24 | C26: kg/s | D26: S_DQO,res ≈ 30% S_DQO,in
A27: Taxa H₂ estimada (r_H₂ = f_H₂ × r_DQO,A) | B27: =B19*B25 | C27: kg/s | D27: Stage 2 §11 — variável de resposta
A28: Produção diária H₂ | B28: =B27*86400 | C28: kg/d | D28: Para conferência com Excel Vinícius
A29: Produção volumétrica H₂ (ρ_H₂=0.0899 kg/Nm³) | B29: =B28/0.0899 | C29: Nm³/d | D29: 1 kg H₂ ≈ 11,12 Nm³
A30: Taxa CH₄ estimada (r_CH₄ = Y_CH₄ × r_DQO,B × ρ_CH₄) | B30: =B20*B26*0.668 | C30: kg/s | D30: ρ_CH₄ = 0,668 kg/Nm³
A31: Produção diária CH₄ volumétrica | B31: =B20*B26*86400 | C31: Nm³/d
A33: KPI PRINCIPAL — H₂/DQO (objetivo do Vinícius)
A34: Eficiência kg H₂/kg DQO afluente (KPI 1) | B34: =B28/B16 | C34: kg H₂/kg DQO | D34: Stage 2 §17 — métrica principal
A35: Eficiência kg H₂/kg DQO consumida na Região A (KPI 2) | B35: =B27/(B25*1.0) | C35: kg H₂/kg DQO | D35: Eficiência intrínseca da fermentação
A37: 1. CFD entrega via Aba 10: Q_DQO_in, Q_gas_total, vazões por DN50, volumes reais por zona (descontando zonas mortas), tempo de residência, fração de fase em cada zona 2. Esta aba calcula KPIs preliminares usando Stage 2 §10/§13 3. Planilha Excel do Vinícius compara e calibra f_H₂ 4. Comparação entre cenários C0/C1/C2 (Stage 2 §15) + C0/C1/C2/C3 (ângulos bocal)
A39: ★ v4.0 — ATUALIZAÇÃO DAS SAÍDAS DOS SEPARADORES
A40: Sep. 20/40/60% — DN50 lateral na parede (3 saídas a 0°, multifásico) Sep. 95% — saída INTERNA para câmara de gás do domo (sem DN50 lateral) Isso significa que o gás coletado no Sep. 95% sobe diretamente para o domo e sai pelo Outlet_Biogas central. NÃO há furo na parede em z=13,87m.

Sheet 10_Reports_STARCCM
B1: FIORA IC — Planilha de Setup CFD/STAR-CCM+ | v3.0
B2: ABA 10 — REPORTS & MONITORS NO STAR-CCM+ (Pós-processamento)
A4: Report Name | B4: Tipo (STAR) | C4: Field Function / Definition | D4: Superfície/Volume | E4: Output / Uso
A5: === ENTRADAS DE MASSA ===
A6: Q_DQO_in_nozzles | B6: Mass Flow | C6: ρ_L × velocity (faseLíquida) | D6: 6× Inlet_Nozzle_01..06 | E6: kg/s líquido entrando
A7: Q_DQO_in_DN100 | B7: Mass Flow | C7: ρ_L × velocity (faseLíquida) | D7: Inlet_DN100_top | E7: kg/s recirculação
A8: Q_gas_in_diffusers | B8: Mass Flow Sum | C8: ṁ_gas (Mass Flow Inlet BC) | D8: 12× Inlet_Diffuser | E8: kg/s biogás recirc.
A9: === SAÍDAS DE MASSA ===
A10: Q_gas_top | B10: Mass Flow | C10: ρ_G × velocity × α_G | D10: Outlet_Biogas (DN100 topo) | E10: kg/s biogás saindo
A11: Q_eff_lateral | B11: Mass Flow | C11: ρ_L × velocity × α_L | D11: Outlet_Effluent (DN100 lat) | E11: kg/s efluente saindo
A12: Q_DN50_20 | B12: Mass Flow | C12: ρ × velocity (multifásico) | D12: Outlet_DN50_20 | E12: Captura sep. 20%
A13: Q_DN50_40 | B13: Mass Flow | C13: ρ × velocity (multifásico) | D13: Outlet_DN50_40 | E13: Captura sep. 40%
A14: Q_DN50_60 | B14: Mass Flow | C14: ρ × velocity (multifásico) | D14: Outlet_DN50_60 | E14: Captura sep. 60%
A15: Q_DN50_95 ★ REMOVIDO v4.0 | B15: Mass Flow | C15: ρ × velocity (multifásico) | D15: Outlet_DN50_95 | E15: Sep. 95% agora sai INTERNO p/ domo — não existe mais DN50 lateral
A16: === VOLUMES DAS REGIÕES (via Field Functions) ===
A17: Volume_Zone_A | B17: Volume Integral | C17: Zone_A | D17: Region (Reactor_Fluid) | E17: m³ úteis da Zona A
A18: Volume_Zone_B | B18: Volume Integral | C18: Zone_B | D18: Region (Reactor_Fluid) | E18: m³ úteis da Zona B
A19: Volume_DeadZones_A | B19: Volume Integral | C19: Zone_A × (mag(V) < 0.001) | D19: Region | E19: m³ de zona morta na A
A20: Volume_DeadZones_B | B20: Volume Integral | C20: Zone_B × (mag(V) < 0.001) | D20: Region | E20: m³ de zona morta na B
A21: === DISTRIBUIÇÃO DE FASES POR ZONA ===
A22: Avg_alpha_lodo_A | B22: Vol-Weighted Avg | C22: Zone_A × α_lodo | D22: Region | E22: Fração média lodo Zona A
A23: Avg_alpha_lodo_B | B23: Vol-Weighted Avg | C23: Zone_B × α_lodo | D23: Region | E23: Fração média lodo Zona B
A24: Avg_alpha_gas_A | B24: Vol-Weighted Avg | C24: Zone_A × α_gas | D24: Region | E24: Fração média gás Zona A
A25: Avg_alpha_gas_B | B25: Vol-Weighted Avg | C25: Zone_B × α_gas | D25: Region | E25: Fração média gás Zona B
A26: Avg_alpha_biochar_A | B26: Vol-Weighted Avg | C26: Zone_A × α_biochar | D26: Region | E26: Fração biochar Zona A
A27: === CISALHAMENTO E HIDRODINÂMICA ===
A28: Avg_shear_A | B28: Vol-Weighted Avg | C28: Zone_A × strainRate | D28: Region | E28: Cisalhamento médio na A (Wu 2015: 57–97% por gás)
A29: Avg_shear_B | B29: Vol-Weighted Avg | C29: Zone_B × strainRate | D29: Region | E29: Cisalhamento médio na B
A30: Max_velocity_global | B30: Maximum | C30: mag(velocity) | D30: Region | E30: Pico de velocidade
A31: Avg_velocity_axial | B31: Vol-Weighted Avg | C31: velocity[2] | D31: Region | E31: Vel. axial média
A32: === TEMPO DE RESIDÊNCIA (DTR via passive scalar) ===
A33: DTR_inlet_pulse | B33: Passive Scalar | C33: Pulso unitário em t=0 nos Inlets | D33: Outlet_Effluent | E33: Curva E(t) → tempo médio τ
A34: MRT_zone_A | B34: Passive Scalar | C34: Tempo médio na Zona A | D34: Region (Zone_A=1) | E34: Tempo de residência médio
A35: === PRESSÃO E PERDA DE CARGA ===
A36: DeltaP_total | B36: Expression | C36: P(z=0) - P(z=14.6) | D36: Region (line probe) | E36: Pa — perda de carga total
A37: DeltaP_separator_20 | B37: Surface Avg diff | C37: P_below - P_above sep.20% | D37: Baffle_Separator_20 | E37: Pa por separador
A38: === KPI FINAL (calculado em Expression Report) ===
A39: Eff_H2_per_DQO | B39: Expression | C39: ($Q_H2_top × 86400) / ($Q_DQO_in_nozzles × 86400) | D39: — | E39: ★ kg H₂/kg DQO afluente — KPI principal Vinícius
A40: Eff_gas_capture_intermediate | B40: Expression | C40: ($Q_DN50_20+$Q_40+$Q_60)/$Q_gas_in | D40: — | E40: % gás capturado nos sep. intermediários
A41: DeadZone_fraction_A | B41: Expression | C41: $Volume_DeadZones_A / $Volume_Zone_A | D41: — | E41: % de volume morto na Zona A
...

Sheet 11_Matriz_Cenarios
B1: FIORA IC — Planilha de Setup CFD/STAR-CCM+ | v3.0
B2: ABA 11 — MATRIZ CONSOLIDADA DE CENÁRIOS DE SIMULAÇÃO
A4: ID | B4: NOZZLE_TANG_ANGLE | C4: Módulo Externo | D4: DQO_in [mg/L] | E4: Φ (k_app,A) | F4: Status / Prioridade | G4: Notas
A5: C0 | B5: 80° | C5: nenhum | D5: 25000 | E5: 1 | F5: ★ CASO BASE — rodar primeiro | G5: Vinícius 16/05 18:04 — caso base oficial
A6: C0_M30 | B6: 80° | C6: M30 (30 s) | D6: 25000 | E6: 1.1 | F6: Stage 2 §14 — sensibilidade | G6: Módulo externo de condicionamento da recirculação
A7: C0_M60 | B7: 80° | C7: M60 (60 s) | D7: 25000 | E7: 1.18 | F7: Stage 2 §14 — sensibilidade | G7: Idem M30 com tempo de exposição maior
A8: C1_75 | B8: 75° | C8: nenhum | D8: 25000 | E8: 1 | F8: Vinícius — sensibilidade bocal | G8: Swirl forte com leve componente radial
A9: C2_70 | B9: 70° | C9: nenhum | D9: 25000 | E9: 1 | F9: Vinícius — sensibilidade bocal | G9: Mais radial, melhor distribuição, menor swirl
A10: C3_85 | B10: 85° | C10: nenhum | D10: 25000 | E10: 1 | F10: Vinícius — sensibilidade bocal | G10: Quase tangente puro, swirl agressivo
A11: C0_DQO_min | B11: 80° | C11: nenhum | D11: 20000 | E11: 1 | F11: Stage 2 §2 — sensibilidade carga | G11: Limite inferior da faixa
A12: C0_DQO_max | B12: 80° | C12: nenhum | D12: 30000 | E12: 1 | F12: Stage 2 §2 — sensibilidade carga | G12: Limite superior da faixa
A13: C0_kapp_min | B13: 80° | C13: nenhum | D13: 25000 | E13: k=0,20 h⁻¹ | F13: Stage 2 §10 — sens. cinética | G13: Limite inferior k_app,A — pós-proc.
A14: C0_kapp_max | B14: 80° | C14: nenhum | D14: 25000 | E14: k=0,50 h⁻¹ | F14: Stage 2 §10 — sens. cinética | G14: Limite superior k_app,A — pós-proc.
A16: TOTAL DE CENÁRIOS PLANEJADOS
A17: Cenários geometria-dependente (re-rodar CAD) | B17: 4 | C17: casos | D17: C0, C1_75, C2_70, C3_85 — cada um requer .step novo
A18: Cenários setup-dependente (mesma geometria) | B18: 4 | C18: casos | D18: M30, M60, DQO_min, DQO_max — só mudar parâmetros
A19: Cenários pós-processamento (não rodar CFD) | B19: 2 | C19: casos | D19: k_app sensibilidade — calculado na Aba 9
A20: TOTAL | B20: 10 | C20: casos | D20: Conforme tabela acima
A22: ESTRATÉGIA DE EXECUÇÃO RECOMENDADA
A23: 1. Rodar C0 (caso base) até convergência hidrodinâmica steady-state 2. Continuar C0 como transiente até 1×TRH (24 h simulados) 3. Avaliar KPIs e validar contra planilha Vinícius 4. Se OK: rodar C1/C2/C3 em paralelo (sensibilidade geométrica) 5. Em série: M30/M60 e DQO_min/max (sensibilidade operacional) 6. Consolidação final: gerar tabela de KPI H₂/DQO e CH₄/DQO para todos os 10 cenários

Sheet 12_Folgas_Criticas
B1: FIORA IC — Planilha de Setup CFD/STAR-CCM+ | v4.0
B2: ABA 12 — VERIFICAÇÕES DE FOLGA CRÍTICAS DO CAD v5.11 (★ NOVA v4.0)
A4: FOLGAS VERTICAIS
A5: Par de Componentes | B5: Cota A [m] | C5: Cota B [m] | D5: Folga [mm] | E5: Status / Observação
A6: Topo Eletrodos × Borda inferior Sep. 20% | B6: 2.65 | C6: 2.92 | D6: +270 | E6: ✅ Margem confortável — corrigido v5.10
A7: Pico Sep. 95% × Saída Efluente Lateral | B7: 14.09 | C7: 14.3 | D7: +210 | E7: ✅ OK
A8: Pico Sep. 95% × Topo do Cilindro | B8: 14.09 | C8: 14.339 | D8: +249 | E8: ✅ OK
A9: Saída Efluente × Topo do Cilindro | B9: 14.3 | C9: 14.339 | D9: +39 | E9: ⚠ Pequena — Vinícius queria 'bem no topo'
A10: Manifold × Topo dos Bocais | B10: 0.175 | C10: 0.232 | D10: +57 | E10: ✅ OK (verticalmente separados)
A11: Topo Difusores × Manifold | B11: 0.025 | C11: 0.125 | D11: +100 | E11: ✅ OK
A12: Topo Eletrodos × Pico Sep. 20% | B12: 2.65 | C12: 3.305 | D12: +655 | E12: ✅ Muito confortável
A14: FOLGAS RADIAIS / AZIMUTAIS
A15: Par de Componentes | B15: Posição A | C15: Posição B | D15: Folga [mm] | E15: Status / Observação
A16: Ramal az=45° × Eletrodo az=0° (linha y=x) | B16: az 45° | C16: az 0° | D16: +297 | E16: ✅ Distância mínima em XY
A17: Ramais × Parede do Reator (extremidade r=0,7m) | B17: r=0,7 m | C17: r=1,045 m | D17: +345 | E17: ✅ OK
A18: Eletrodo r=0,68 (borda ext.) × Parede | B18: r=0,94 m | C18: r=1,045 m | D18: +105 | E18: ✅ OK (memorial v1.0)
A19: Eletrodo r=0,68 (borda int.) × DN100 (r=0,05) | B19: r=0,42 m | C19: r=0,05 m | D19: +370 | E19: ✅ Muito OK
A20: Difusor externo × Parede | B20: r=0,80 m | C20: r=1,045 m | D20: +245 | E20: ✅ OK
A21: Difusor interno × DN100 central | B21: r=0,35 m | C21: r=0,05 m | D21: +300 | E21: ✅ OK
A22: DN100 retorno (raio 50mm) × Λs centrais (vale) | B22: r=0,05 m | C22: vale entre Λs | D22: +102 | E22: ✅ Passa no vale entre Λs centrais
A24: FOLGAS ANGULARES (Δθ)
A25: Par de Componentes | B25: Az A [°] | C25: Az B [°] | D25: Δθ [°] | E25: Status / Observação
A26: Ramais × Eletrodos | B26: 45/135/225/315 | C26: 0/180 | D26: 45° | E26: ✅ Mínima Δθ = 45°
A27: Ramais × Bocais | B27: 45/135/225/315 | C27: 0/60/120/180/... | D27: 15° | E27: ✅ Mínima Δθ = 15°
A28: Ramais × Difusores (setores) | B28: 45/135/225/315 | C28: 30/90/150/210/270/330 | D28: 15° | E28: ✅ Mínima Δθ = 15°
A29: Bocais × Eletrodos | B29: 0/60/120/180/... | C29: 0/180 | D29: 0° | E29: ✅ Sobreposição mas em z diferentes
A30: Difusores × Bocais | B30: 30/90/150/... | C30: 0/60/120/... | D30: 30° | E30: ✅ Difusores ENTRE bocais
A33: AÇÃO RECOMENDADA
A34: Antes de cada geração de geometria (v5.x → v5.x+1), executar o script FIORA_IC_geometry_v5_11.py — ele chama _check_clearances() automaticamente no início e levanta AssertionError se alguma folga vertical ficar < 50 mm. Bug histórico detectado (v5.9 → v5.10): cota nominal do separador era interpretada como pico do Λ, mas as placas inclinadas desciam 385 mm abaixo do pico, criando sobreposição com o topo dos eletrodos. Corrigido na v5.10 interpretando pct × H como BORDA INFERIOR das placas externas.

Sheet 13_Manifold_Recirculacao
B1: FIORA IC — Planilha de Setup CFD/STAR-CCM+ | v4.0
B2: ABA 13 — MANIFOLD DE 4 RAMAIS DN50 (★ NOVA v4.0)
A4: PARÂMETROS GEOMÉTRICOS — TUBO PRINCIPAL DN100
A5: Diâmetro nominal | B5: 0.1 | C5: m | D5: DN100 — Vinícius
A6: Espessura de parede | B6: 0.004 | C6: m | D6: 4 mm — padrão DN100
A7: Diâmetro interno | B7: =B5-2*B6 | C7: m | D7: =92 mm
A8: Cota inferior (manifold) | B8: 0.15 | C8: m | D8: ★ Vinícius 18/05 17:06: 'Até 15 cm do fundo'
A9: Cota superior (próximo ao domo) | B9: 14.29 | C9: m | D9: =H − TOP_DEPTH − 0,05
A10: Comprimento do tubo principal | B10: =B9-B8 | C10: m | D10: =14,14 m
A12: PARÂMETROS GEOMÉTRICOS — 4 RAMAIS DN50
A13: Diâmetro nominal de cada ramal | B13: 0.05 | C13: m | D13: ★ Vinícius 18/05 17:06: DN50 confirmado
A14: Espessura de parede | B14: 0.004 | C14: m | D14: 4 mm
A15: Comprimento de cada ramal | B15: 0.7 | C15: m | D15: Vinícius: 'pode manter como propôs'
A16: Cota dos ramais (= manifold) | B16: =B8 | C16: m | D16: Mesma cota do manifold
A17: Azimutes dos 4 ramais | B17: 45° / 135° / 225° / 315° | C17: — | D17: Entre bocais, fora dos eletrodos
A18: Posição final do ramal (x,y) — az 45° | B18: (+0,495; +0,495) | C18: m | D18: =0,7 × cos/sin(45°)
A19: Folga radial à parede | B19: =1.045-0.70 | C19: m | D19: =R_reator − 0,7 = 0,345 m
A20: Final dos ramais | B20: Aberto (descarga livre) | C20: — | D20: Vinícius: 'pode manter como propôs'
A22: CONSERVAÇÃO DE ÁREA HIDRÁULICA
A23: Área da seção do tubo principal (DN100) | B23: =PI()*(B5/2)^2 | C23: m² | D23: =7,854 ×10⁻³ m²
A24: Área de cada ramal (DN50) | B24: =PI()*(B13/2)^2 | C24: m² | D24: =1,963 ×10⁻³ m²
A25: Área total dos 4 ramais | B25: =4*B24 | C25: m² | D25: =7,854 ×10⁻³ m²
A26: ★ Razão Área_4ramais / Área_DN100 | B26: =B25/B23 | C26: — | D26: =1,000 ✓ Conservação OK
A28: BC NO STAR-CCM+
A29: 1. Toda a estrutura (tubo principal + 4 ramais) é UM ÚNICO baffle No-slip Wall no STAR-CCM+ (separa fluxo interno descendente do externo ascendente). 2. APENAS a face SUPERIOR do tubo principal é Velocity Inlet: • Q = 350 m³/d (recirculação líquida) • Direção: −Z (descendente) • Temperatura: 35°C • Fase: líquida 3. Os 4 ramais descarregam LIVREMENTE no domínio (extremidades abertas). No CFD, basta o sólido baffle ter aberturas nas extremidades.
